Workbook
Name ConstantHH: TormekCalc!$C$19
Name ConstantHV: TormekCalc!$C$17
Name ConstantVF: TormekCalc!$C$22
Name ConstantVH: TormekCalc!$C$20
Name ConstantVV: TormekCalc!$C$18
Name DefaultConstantFVBBody: Settings!$F$16
Name DefaultConstantHH: Settings!$F$14
Name DefaultConstantHV: Settings!$F$12
Name DefaultConstantVF: Settings!$F$17
Name DefaultConstantVH: Settings!$F$15
Name DefaultConstantVV: Settings!$F$13
Name DefaultEdgeThickness: Settings!$F$21
Name DefaultFVBDistance: Settings!$F$9
Name DefaultGA: Settings!$F$6
Name DefaultJPL: Settings!$F$5
Name DefaultKJD: Settings!$F$7
Name DefaultTJD: Settings!$F$8
Name DefaultUSBDia: Settings!$F$11
Name DefaultWheelDia: Settings!$F$20
Name EmptyData: Settings!$F$33
Name FVBOffset: TormekCalc!$C$13
Name InCellName01: Settings!$C$5
Name InCellName02: Settings!$C$6
Name JigsAll: Jigs!$W$6:INDEX(Jigs!$W$6:$W$55,COUNTIF(Jigs!$W$6:$W$55,"?*"))
Name JigsKnivesDList: Jigs!$S$6:INDEX(Jigs!$S$6:$S$55,COUNTIF(Jigs!$S$6:$S$55,"?*"))
Name JigsToolsAllDList: Jigs!$V$6:INDEX(Jigs!$V$6:$V$55,COUNTIF(Jigs!$V$6:$V$55,"?*"))
Name JigsToolsDList: Jigs!$T$6:INDEX(Jigs!$T$6:$T$55,COUNTIF(Jigs!$T$6:$T$55,"?*"))
Name KnivesDList: OFFSET(KnivesListTable[[#Headers],[KnivesList]],1,0,COUNTIFS(KnivesListTable[KnivesList],"?*"),1)
Name KnivesGrindDList: OFFSET(GrindTypesTable[[#Headers],[Knives grind]],1,0,COUNTIFS(GrindTypesTable[Knives grind],"?*"),1)
Name MachinesAO: Settings!$H$24
Name MachinesCG: Settings!$H$23
Name MachinesConstantFVBBody: Settings!$H$15
Name MachinesConstantHF: Settings!$H$17
Name MachinesConstantHH: Settings!$H$13
Name MachinesConstantHV: Settings!$H$11
Name MachinesConstantVF: Settings!$H$16
Name MachinesConstantVH: Settings!$H$14
Name MachinesConstantVV: Settings!$H$12
Name MachinesDList: IF(COUNTIFS(OFFSET(Machines[#Headers],2,1),"<>")=0,"",OFFSET(Machines[[#Headers],[Setting description]],0,1):INDEX(OFFSET(Machines[#Headers],0,1),COUNTIFS(OFFSET(Machines[#Headers],2,1),"?*")))
Name MachinesUSBDia: Settings!$H$10
Name Max_H_HFUSB_105: Settings!$F$27
Name Max_H_HFUSB_430: Settings!$F$31
Name Max_H_VUSB_105: Settings!$F$25
Name Max_H_VUSB_430: Settings!$F$29
Name Min_FVB_Distance: Settings!$F$23
Name Min_H_HFUSB_105: Settings!$F$26
Name Min_H_HFUSB_430: Settings!$F$30
Name Min_H_VUSB_105: Settings!$F$24
Name Min_H_VUSB_430: Settings!$F$28
Name NotAvailable: Settings!$F$35
Name SetMachines: Settings!$F$34
Name SheetName01: Settings!$B$5
Name SheetName02: Settings!$B$6
Name ToolsDList: OFFSET(ToolsListTable[[#Headers],[ToolsList]],1,0,COUNTIFS(ToolsListTable[ToolsList],"?*"),1)
Name ToolsGrindDList: OFFSET(GrindTypesTable[[#Headers],[Tools grind]],1,0,COUNTIFS(GrindTypesTable[Tools grind],"?*"),1)
Name VariableCG: TormekCalc!$C$27
Name VariableDK: TormekCalc!$C$28
Name VariableGA: TormekCalc!$C$11
Name VariableJC: TormekCalc!$C$26
Name VariableJG: TormekCalc!$C$25

Sheet TormekCalc
B2: TormekCalc2
B4: Database | C4: Knives | E4: =IF($C$4=""," <-- " & EmptyData,"") | F4: Wheel | G4: SG-250 | H4: SB-250 | I4: Sun Tiger 800 | J4: SJ-250 | K4: Sun Tiger 4000 | L4: DC-250 | M4: DF-250 | N4: DE-250 | O4: LA-220 PA-77 | P4: LA-220 FlexCut | Q4: LA-220 Chromox | R4: Custom 1 | S4: Custom 2 | T4: Wheel XY
G5: =IF(ISERROR(CELL("width",G$4)),F5+1,N(F5)+SUBTOTAL(103,G$4)*(CELL("width",G$4)>0)) -> 1 | H5: =IF(ISERROR(CELL("width",H$4)),G5+1,N(G5)+SUBTOTAL(103,H$4)*(CELL("width",H$4)>0)) -> 2 | I5: =IF(ISERROR(CELL("width",I$4)),H5+1,N(H5)+SUBTOTAL(103,I$4)*(CELL("width",I$4)>0)) -> 3 | J5: =IF(ISERROR(CELL("width",J$4)),I5+1,N(I5)+SUBTOTAL(103,J$4)*(CELL("width",J$4)>0)) -> 4 | K5: =IF(ISERROR(CELL("width",K$4)),J5+1,N(J5)+SUBTOTAL(103,K$4)*(CELL("width",K$4)>0)) -> 5 | L5: =IF(ISERROR(CELL("width",L$4)),K5+1,N(K5)+SUBTOTAL(103,L$4)*(CELL("width",L$4)>0)) -> 6 | M5: =IF(ISERROR(CELL("width",M$4)),L5+1,N(L5)+SUBTOTAL(103,M$4)*(CELL("width",M$4)>0)) -> 7 | N5: =IF(ISERROR(CELL("width",N$4)),M5+1,N(M5)+SUBTOTAL(103,N$4)*(CELL("width",N$4)>0)) -> 8 | ... T5: =IF(ISERROR(CELL("width",T$4)),S5+1,N(S5)+SUBTOTAL(103,T$4)*(CELL("width",T$4)>0)) -> 14
C6: Used value | D6: Input | G6: =IF(ISERROR(INDEX($G$4:$T$4,MATCH(COLUMNS($G6:G6),$G$5:$T$5,0))),"",INDEX($G$4:$T$4,MATCH(COLUMNS($G6:G6),$G$5:$T$5,0))) -> SG-250 | H6: =IF(ISERROR(INDEX($G$4:$T$4,MATCH(COLUMNS($G6:H6),$G$5:$T$5,0))),"",INDEX($G$4:$T$4,MATCH(COLUMNS($G6:H6),$G$5:$T$5,0))) -> SB-250 | I6: =IF(ISERROR(INDEX($G$4:$T$4,MATCH(COLUMNS($G6:I6),$G$5:$T$5,0))),"",INDEX($G$4:$T$4,MATCH(COLUMNS($G6:I6),$G$5:$T$5,0))) -> Sun Tiger 800 | J6: =IF(ISERROR(INDEX($G$4:$T$4,MATCH(COLUMNS($G6:J6),$G$5:$T$5,0))),"",INDEX($G$4:$T$4,MATCH(COLUMNS($G6:J6),$G$5:$T$5,0))) -> SJ-250 | K6: =IF(ISERROR(INDEX($G$4:$T$4,MATCH(COLUMNS($G6:K6),$G$5:$T$5,0))),"",INDEX($G$4:$T$4,MATCH(COLUMNS($G6:K6),$G$5:$T$5,0))) -> Sun Tiger 4000 | L6: =IF(ISERROR(INDEX($G$4:$T$4,MATCH(COLUMNS($G6:L6),$G$5:$T$5,0))),"",INDEX($G$4:$T$4,MATCH(COLUMNS($G6:L6),$G$5:$T$5,0))) -> DC-250 | M6: =IF(ISERROR(INDEX($G$4:$T$4,MATCH(COLUMNS($G6:M6),$G$5:$T$5,0))),"",INDEX($G$4:$T$4,MATCH(COLUMNS($G6:M6),$G$5:$T$5,0))) -> DF-250 | N6: =IF(ISERROR(INDEX($G$4:$T$4,MATCH(COLUMNS($G6:N6),$G$5:$T$5,0))),"",INDEX($G$4:$T$4,MATCH(COLUMNS($G6:N6),$G$5:$T$5,0))) -> DE-250 | ... T6: =IF(ISERROR(INDEX($G$4:$T$4,MATCH(COLUMNS($G6:T6),$G$5:$T$5,0))),"",INDEX($G$4:$T$4,MATCH(COLUMNS($G6:T6),$G$5:$T$5,0))) -> Wheel XY
B7: =IF($C$4=SheetName02,InCellName02,InCellName01) -> Knife | C7: 001 ANV P200
B8: Jig selection | C8: SVM-45
B10: =IF($C$4=SheetName01,"Jig projection length X [mm]","Jig or Tool projection length X [mm]") -> Jig projection length X [mm] | C10: =IF($D$10=0,IF($C$8="", IF(AND($C$7<>"",NOT(ISERROR(MATCH($C$7,INDIRECT($C$4&"ListTable["&INDIRECT("$C$4")&"List]"),0)))), IF(INDEX(INDIRECT($C$4&"[Jig type]"),MATCH($C$7,INDIRECT($C$4&"ListTable["&INDIRECT("$C$4")&"List]"),0))="",IF(ISNUMBER(INDEX(INDIRECT($C$4&"[Jig proj. X]"),MATCH($C$7,INDIRECT($C$4&"ListTable["&INDIRECT("$C$4")&"List]"),0))),INDEX(INDIRECT($C$4&"[Jig proj. X]"),MATCH($C$7,INDIRECT($C$4&"ListTable["&INDIRECT("$C$4")&"List]"),0)),DefaultJPL),IF(NOT(ISERROR(MATCH(INDEX(INDIRECT($C$4&"[Jig type]"),MATCH($C$7,INDIRECT($C$4&"ListTable["&INDIRECT("$C$4")&"List]"),0)),Jigs!$D6:$D105,0))),IF(ISNUMBER(INDEX(Jigs!$H6:$H105,MATCH(INDEX(INDIRECT($C$4&"[Jig type]"),MATCH($C$7,INDIRECT($C$4&"ListTable["&INDIRECT("$C$4")&"List]"),0)),Jigs!$D6:$D105,0),0)),IF(INDEX(Jigs!$H6:$H105,MATCH(INDEX(INDIRECT($C$4&"[Jig type]"),MATCH($C$7,INDIRECT($C$4&"ListTable["&INDIRECT("$C$4")&"List]"),0)),Jigs!$D6:$D105,0),0)=0, IF(ISNUMBER(INDEX(INDIRECT($C$4&"[Jig proj. X]"),MATCH($C$7,INDIRECT($C$4&"ListTable["&INDIRECT("$C$4")&"List]"),0))),INDEX(INDIRECT($C$4&"[Jig proj. X]"),MATCH($C$7,INDIRECT($C$4&"ListTable["&INDIRECT("$C$4")&"List]"),0)),DefaultJPL),INDEX(Jigs!$H6:$H105,MATCH(INDEX(INDIRECT($C$4&"[Jig type]"),MATCH($C$7,INDIRECT($C$4&"ListTable["&INDIRECT("$C$4")&"List]"),0)),Jigs!$D6:$D105,0),0)+IF(ISNUMBER(INDEX(INDIRECT($C$4&"[Jig proj. X]"),MATCH($C$7,INDIRECT($C$4&"ListTable["&INDIRECT("$C$4")&"List]"),0))),INDEX(INDIRECT($C$4&"[Jig proj. X]"),MATCH($C$7,INDIRECT($C$4&"ListTable["&INDIRECT("$C$4")&"List]"),0)),DefaultJPL) ),DefaultJPL),DefaultJPL)),DefaultJPL), IF(NOT(ISERROR(MATCH($C$8,Jigs!$D6:$D105,0))),IF(AND(ISNUMBER(INDEX(Jigs!$H6:$H105,MATCH($C$8,Jigs!$D$6:$D$105,0))),INDEX(Jigs!$H6:$H105,MATCH($C$8,Jigs!$D$6:$D$105,0))<>0),INDEX(Jigs!$H6:$H105,MATCH($C$8,Jigs!$D$6:$D$105,0))+$D$10,IF(AND($C$7<>"",NOT(ISERROR(MATCH($C$7,INDIRECT($C$4&"ListTable["&INDIRECT("$C$4")&"List]"),0)))),IF(ISNUMBER(INDEX(INDIRECT($C$4&"[Jig proj. X]"),MATCH($C$7,INDIRECT($C$4&"ListTable["&INDIRECT("$C$4")&"List]"),0))),INDEX(INDIRECT($C$4&"[Jig proj. X]"),MATCH($C$7,INDIRECT($C$4&"ListTable["&INDIRECT("$C$4")&"List]"),0)),DefaultJPL),DefaultJPL)),DefaultJPL)), IF($C$8="",IF(ISNUMBER($D$10),IF($C$7="",$D$10,IF($C$4="",$D$10,IF(INDEX(INDIRECT($C$4&"[Jig type]"),MATCH($C$7,INDIRECT($C$4&"ListTable["&INDIRECT("$C$4")&"List]"),0))="",IF(ISNUMBER(INDEX(INDIRECT($C$4&"[Jig proj. X]"),MATCH($C$7,INDIRECT($C$4&"ListTable["&INDIRECT("$C$4")&"List]"),0))),INDEX(INDIRECT($C$4&"[Jig proj. X]"),MATCH($C$7,INDIRECT($C$4&"ListTable["&INDIRECT("$C$4")&"List]"),0)),DefaultJPL),IF(NOT(ISERROR(MATCH(INDEX(INDIRECT($C$4&"[Jig type]"),MATCH($C$7,INDIRECT($C$4&"ListTable["&INDIRECT("$C$4")&"List]"),0)),Jigs!$D6:$D105,0))),IF(ISNUMBER(INDEX(Jigs!$H6:$H105,MATCH(INDEX(INDIRECT($C$4&"[Jig type]"),MATCH($C$7,INDIRECT($C$4&"ListTable["&INDIRECT("$C$4")&"List]"),0)),Jigs!$D6:$D105,0),0)),IF(INDEX(Jigs!$H6:$H105,MATCH(INDEX(INDIRECT($C$4&"[Jig type]"),MATCH($C$7,INDIRECT($C$4&"ListTable["&INDIRECT("$C$4")&"List]"),0)),Jigs!$D6:$D105,0),0)=0,$D$10,INDEX(Jigs!$H6:$H105,MATCH(INDEX(INDIRECT($C$4&"[Jig type]"),MATCH($C$7,INDIRECT($C$4&"ListTable["&INDIRECT("$C$4")&"List]"),0)),Jigs!$D6:$D105,0),0)+$D$10),DefaultJPL), DefaultJPL)))),DefaultJPL),IF(NOT(ISERROR(MATCH($C$8,Jigs!$D6:$D105,0))),IF(AND(ISNUMBER(INDEX(Jigs!$H6:$H105,MATCH($C$8,Jigs!$D$6:$D$105,0))),INDEX(Jigs!$H6:$H105,MATCH($C$8,Jigs!$D$6:$D$105,0))<>0),INDEX(Jigs!$H6:$H105,MATCH($C$8,Jigs!$D$6:$D$105,0))+$D$10,$D$10),DefaultJPL))) -> 138 | F10: Grit | G10: 220 | H10: 220 | I10: 800 | J10: 4000 | K10: 4000 | L10: 360 | M10: 600 | N10: 1200 | O10: - | P10: - | Q10: - | R10: - | S10: - | T10: 80
B11: Grinding angle Δ [°] | C11: =IF($D$11=0,IF(AND($C$7<>"",NOT(ISERROR(MATCH($C$7,INDIRECT($C$4&"ListTable["&INDIRECT("$C$4")&"List]"),0)))),IF(ISNUMBER(INDEX(INDIRECT($C$4&"[Grinded]"),MATCH($C$7,INDIRECT($C$4&"ListTable["&INDIRECT("$C$4")&"List]"),0))),INDEX(INDIRECT($C$4&"[Grinded]"),MATCH($C$7,INDIRECT($C$4&"ListTable["&INDIRECT("$C$4")&"List]"),0)),DefaultGA),DefaultGA),$D$11) -> 20 | F11: Nominal diameter | G11: 250 | H11: 250 | I11: 254 | J11: 250 | K11: 254 | L11: 250 | M11: 250 | N11: 250 | O11: 220 | P11: 220 | Q11: 220 | R11: - | S11: - | T11: 200
B12: Jig or Tool diameter M [mm] | C12: =IF($D$12=0,IF(C8="",IF(AND($C$7<>"",NOT(ISERROR(MATCH($C$7,INDIRECT($C$4&"ListTable["&INDIRECT("$C$4")&"List]"),0)))),IF(ISNUMBER(MATCH(INDEX(INDIRECT($C$4&"[Jig type]"),MATCH($C$7,INDIRECT($C$4&"ListTable["&INDIRECT("$C$4")&"List]"),0)),JigListsTable[JigsToolsNC],0)),NotAvailable,IF(ISNUMBER(INDEX(INDIRECT($C$4&"[Jig dia M]"),MATCH($C$7,INDIRECT($C$4&"ListTable["&INDIRECT("$C$4")&"List]"),0))),INDEX(INDIRECT($C$4&"[Jig dia M]"),MATCH($C$7,INDIRECT($C$4&"ListTable["&INDIRECT("$C$4")&"List]"),0)),IF($C$4=SheetName02,DefaultTJD,DefaultKJD))),IF($C$4=SheetName02,DefaultTJD,DefaultKJD)),IF(NOT(ISERROR(MATCH($C$8,Jigs!$D6:$D105,0))),IF(AND(ISNUMBER(INDEX(Jigs!$F6:$F105,MATCH($C$8,Jigs!$D$6:$D$105,0))),INDEX(Jigs!$F6:$F105,MATCH($C$8,Jigs!$D$6:$D$105,0))>0),INDEX(Jigs!$F6:$F105,MATCH($C$8,Jigs!$D$6:$D$105,0)),IF($C$4=SheetName02,DefaultTJD,DefaultKJD)),IF($C$4=SheetName02,DefaultTJD,DefaultKJD))),$D$12) -> 12 | F12: Real diameter D [mm] | G12: 250 | H12: 249 | I12: 253.5 | J12: 248.5 | K12: 254 | L12: 250 | M12: 250 | N12: 250 | O12: 215 | P12: 214.5 | Q12: 214.8 | R12: 250 | S12: 250 | T12: 195
B13: Frontal vertical base offset F [mm] | C13: =IF(OR($D$13<Min_FVB_Distance,ISTEXT($D$13)),DefaultFVBDistance,$D$13) -> 24.5 | F13: Machine | M13: Machine 1 | N13: Machine 2 | T13: Machine 3
B14: =IF(AND($C$7<>"",NOT(ISERROR(MATCH($C$7,INDIRECT($C$4&"ListTable["&INDIRECT("$C$4")&"List]"),0)))), IF($C$4=SheetName01,"Last used jig | Clamping from Guard / Spine [mm]",IF($C$4=SheetName02,"Last used jig | Clamping from Jig / Side [mm]","")),"") -> Last used jig | Clamping from Guard / Spine [mm] | C14: =IF(AND($C$7<>"",NOT(ISERROR(MATCH($C$7,INDIRECT($C$4&"ListTable["&INDIRECT("$C$4")&"List]"),0)))),IF(INDEX(INDIRECT($C$4&"[Jig type]"),MATCH($C$7,INDIRECT($C$4&"ListTable["&INDIRECT("$C$4")&"List]"),0))<>"",INDEX(INDIRECT($C$4&"[Jig type]"),MATCH($C$7,INDIRECT($C$4&"ListTable["&INDIRECT("$C$4")&"List]"),0)),NotAvailable),"") -> SVM-45 E | D14: =IF(AND($C$7<>"",NOT(ISERROR(MATCH($C$7,INDIRECT($C$4&"ListTable["&INDIRECT("$C$4")&"List]"),0)))),IF(INDEX(INDIRECT($C$4&"[from G]"),MATCH($C$7,INDIRECT($C$4&"ListTable["&INDIRECT("$C$4")&"List]"),0))<>"",TEXT(INDEX(INDIRECT($C$4&"[from G]"),MATCH($C$7,INDIRECT($C$4&"ListTable["&INDIRECT("$C$4")&"List]"),0)),"0,0"),"?")&" / "&IF(INDEX(INDIRECT($C$4&"[from S]"),MATCH($C$7,INDIRECT($C$4&"ListTable["&INDIRECT("$C$4")&"List]"),0))<>"",TEXT(INDEX(INDIRECT($C$4&"[from S]"),MATCH($C$7,INDIRECT($C$4&"ListTable["&INDIRECT("$C$4")&"List]"),0)),"0,0"),"?"),"") -> 4,0 / 11,5
B15: =IF(AND($C$7<>"",NOT(ISERROR(MATCH($C$7,INDIRECT($C$4&"ListTable["&INDIRECT("$C$4")&"List]"),0)))), IF(INDEX(INDIRECT($C$4&"[Jig setting]"),MATCH($C$7,INDIRECT($C$4&"ListTable["&INDIRECT("$C$4")&"List]"),0))<>"","Last jig setting",""),"") | C15: =IF(AND($C$7<>"",NOT(ISERROR(MATCH($C$7,INDIRECT($C$4&"ListTable["&INDIRECT("$C$4")&"List]"),0)))), IF(INDEX(INDIRECT($C$4&"[Jig setting]"),MATCH($C$7,INDIRECT($C$4&"ListTable["&INDIRECT("$C$4")&"List]"),0))<>"",TEXT(INDEX(INDIRECT($C$4&"[Jig setting]"),MATCH($C$7,INDIRECT($C$4&"ListTable["&INDIRECT("$C$4")&"List]"),0)),"0"),""),"") | F15: T USB [mm] | G15: =IF(G13="",IF(ISERROR(SQRT(VariableCG^2+(G12/2)^2+2*VariableCG*(G12/2)*SIN(RADIANS(VariableGA-VariableDK)))+VariableUSBDia/2-(G12/2)),"-",IF(SQRT(VariableCG^2+(G12/2)^2+2*VariableCG*(G12/2)*SIN(RADIANS(VariableGA-VariableDK)))+VariableUSBDia/2-(G12/2)<0,"-",SQRT(VariableCG^2+(G12/2)^2+2*VariableCG*(G12/2)*SIN(RADIANS(VariableGA-VariableDK)))+VariableUSBDia/2-(G12/2))),IF(OR(ISERROR(SQRT(VLOOKUP(MachinesCG,Machines[],MATCH(G13,Machines[#Headers],0),FALSE)^2+(G12/2)^2+2*VLOOKUP(MachinesCG,Machines[],MATCH(G13,Machines[#Headers],0),FALSE)*(G12/2)*SIN(RADIANS(VariableGA-VLOOKUP(MachinesAO,Machines[],MATCH(G13,Machines[#Headers],0),FALSE))))+VLOOKUP(MachinesUSBDia,Machines[],MATCH(G13,Machines[#Headers],0),FALSE)/2-(G12/2)),NOT(ISNUMBER(VLOOKUP(MachinesUSBDia,Machines[],MATCH(G13,Machines[#Headers],0),FALSE)))),"-",IF(SQRT(VLOOKUP(MachinesCG,Machines[],MATCH(G13,Machines[#Headers],0),FALSE)^2+(G12/2)^2+2*VLOOKUP(MachinesCG,Machines[],MATCH(G13,Machines[#Headers],0),FALSE)*(G12/2)*SIN(RADIANS(VariableGA-VLOOKUP(MachinesAO,Machines[],MATCH(G13,Machines[#Headers],0),FALSE))))+VLOOKUP(MachinesUSBDia,Machines[],MATCH(G13,Machines[#Headers],0),FALSE)/2-(G12/2)<0,"-",SQRT(VLOOKUP(MachinesCG,Machines[],MATCH(G13,Machines[#Headers],0),FALSE)^2+(G12/2)^2+2*VLOOKUP(MachinesCG,Machines[],MATCH(G13,Machines[#Headers],0),FALSE)*(G12/2)*SIN(RADIANS(VariableGA-VLOOKUP(MachinesAO,Machines[],MATCH(G13,Machines[#Headers],0),FALSE))))+VLOOKUP(MachinesUSBDia,Machines[],MATCH(G13,Machines[#Headers],0),FALSE)/2-(G12/2)))) -> 85.109252 | H15: =IF(H13="",IF(ISERROR(SQRT(VariableCG^2+(H12/2)^2+2*VariableCG*(H12/2)*SIN(RADIANS(VariableGA-VariableDK)))+VariableUSBDia/2-(H12/2)),"-",IF(SQRT(VariableCG^2+(H12/2)^2+2*VariableCG*(H12/2)*SIN(RADIANS(VariableGA-VariableDK)))+VariableUSBDia/2-(H12/2)<0,"-",SQRT(VariableCG^2+(H12/2)^2+2*VariableCG*(H12/2)*SIN(RADIANS(VariableGA-VariableDK)))+VariableUSBDia/2-(H12/2))),IF(OR(ISERROR(SQRT(VLOOKUP(MachinesCG,Machines[],MATCH(H13,Machines[#Headers],0),FALSE)^2+(H12/2)^2+2*VLOOKUP(MachinesCG,Machines[],MATCH(H13,Machines[#Headers],0),FALSE)*(H12/2)*SIN(RADIANS(VariableGA-VLOOKUP(MachinesAO,Machines[],MATCH(H13,Machines[#Headers],0),FALSE))))+VLOOKUP(MachinesUSBDia,Machines[],MATCH(H13,Machines[#Headers],0),FALSE)/2-(H12/2)),NOT(ISNUMBER(VLOOKUP(MachinesUSBDia,Machines[],MATCH(H13,Machines[#Headers],0),FALSE)))),"-",IF(SQRT(VLOOKUP(MachinesCG,Machines[],MATCH(H13,Machines[#Headers],0),FALSE)^2+(H12/2)^2+2*VLOOKUP(MachinesCG,Machines[],MATCH(H13,Machines[#Headers],0),FALSE)*(H12/2)*SIN(RADIANS(VariableGA-VLOOKUP(MachinesAO,Machines[],MATCH(H13,Machines[#Headers],0),FALSE))))+VLOOKUP(MachinesUSBDia,Machines[],MATCH(H13,Machines[#Headers],0),FALSE)/2-(H12/2)<0,"-",SQRT(VLOOKUP(MachinesCG,Machines[],MATCH(H13,Machines[#Headers],0),FALSE)^2+(H12/2)^2+2*VLOOKUP(MachinesCG,Machines[],MATCH(H13,Machines[#Headers],0),FALSE)*(H12/2)*SIN(RADIANS(VariableGA-VLOOKUP(MachinesAO,Machines[],MATCH(H13,Machines[#Headers],0),FALSE))))+VLOOKUP(MachinesUSBDia,Machines[],MATCH(H13,Machines[#Headers],0),FALSE)/2-(H12/2)))) -> 85.220314 | I15: =IF(I13="",IF(ISERROR(SQRT(VariableCG^2+(I12/2)^2+2*VariableCG*(I12/2)*SIN(RADIANS(VariableGA-VariableDK)))+VariableUSBDia/2-(I12/2)),"-",IF(SQRT(VariableCG^2+(I12/2)^2+2*VariableCG*(I12/2)*SIN(RADIANS(VariableGA-VariableDK)))+VariableUSBDia/2-(I12/2)<0,"-",SQRT(VariableCG^2+(I12/2)^2+2*VariableCG*(I12/2)*SIN(RADIANS(VariableGA-VariableDK)))+VariableUSBDia/2-(I12/2))),IF(OR(ISERROR(SQRT(VLOOKUP(MachinesCG,Machines[],MATCH(I13,Machines[#Headers],0),FALSE)^2+(I12/2)^2+2*VLOOKUP(MachinesCG,Machines[],MATCH(I13,Machines[#Headers],0),FALSE)*(I12/2)*SIN(RADIANS(VariableGA-VLOOKUP(MachinesAO,Machines[],MATCH(I13,Machines[#Headers],0),FALSE))))+VLOOKUP(MachinesUSBDia,Machines[],MATCH(I13,Machines[#Headers],0),FALSE)/2-(I12/2)),NOT(ISNUMBER(VLOOKUP(MachinesUSBDia,Machines[],MATCH(I13,Machines[#Headers],0),FALSE)))),"-",IF(SQRT(VLOOKUP(MachinesCG,Machines[],MATCH(I13,Machines[#Headers],0),FALSE)^2+(I12/2)^2+2*VLOOKUP(MachinesCG,Machines[],MATCH(I13,Machines[#Headers],0),FALSE)*(I12/2)*SIN(RADIANS(VariableGA-VLOOKUP(MachinesAO,Machines[],MATCH(I13,Machines[#Headers],0),FALSE))))+VLOOKUP(MachinesUSBDia,Machines[],MATCH(I13,Machines[#Headers],0),FALSE)/2-(I12/2)<0,"-",SQRT(VLOOKUP(MachinesCG,Machines[],MATCH(I13,Machines[#Headers],0),FALSE)^2+(I12/2)^2+2*VLOOKUP(MachinesCG,Machines[],MATCH(I13,Machines[#Headers],0),FALSE)*(I12/2)*SIN(RADIANS(VariableGA-VLOOKUP(MachinesAO,Machines[],MATCH(I13,Machines[#Headers],0),FALSE))))+VLOOKUP(MachinesUSBDia,Machines[],MATCH(I13,Machines[#Headers],0),FALSE)/2-(I12/2)))) -> 84.724319 | J15: =IF(J13="",IF(ISERROR(SQRT(VariableCG^2+(J12/2)^2+2*VariableCG*(J12/2)*SIN(RADIANS(VariableGA-VariableDK)))+VariableUSBDia/2-(J12/2)),"-",IF(SQRT(VariableCG^2+(J12/2)^2+2*VariableCG*(J12/2)*SIN(RADIANS(VariableGA-VariableDK)))+VariableUSBDia/2-(J12/2)<0,"-",SQRT(VariableCG^2+(J12/2)^2+2*VariableCG*(J12/2)*SIN(RADIANS(VariableGA-VariableDK)))+VariableUSBDia/2-(J12/2))),IF(OR(ISERROR(SQRT(VLOOKUP(MachinesCG,Machines[],MATCH(J13,Machines[#Headers],0),FALSE)^2+(J12/2)^2+2*VLOOKUP(MachinesCG,Machines[],MATCH(J13,Machines[#Headers],0),FALSE)*(J12/2)*SIN(RADIANS(VariableGA-VLOOKUP(MachinesAO,Machines[],MATCH(J13,Machines[#Headers],0),FALSE))))+VLOOKUP(MachinesUSBDia,Machines[],MATCH(J13,Machines[#Headers],0),FALSE)/2-(J12/2)),NOT(ISNUMBER(VLOOKUP(MachinesUSBDia,Machines[],MATCH(J13,Machines[#Headers],0),FALSE)))),"-",IF(SQRT(VLOOKUP(MachinesCG,Machines[],MATCH(J13,Machines[#Headers],0),FALSE)^2+(J12/2)^2+2*VLOOKUP(MachinesCG,Machines[],MATCH(J13,Machines[#Headers],0),FALSE)*(J12/2)*SIN(RADIANS(VariableGA-VLOOKUP(MachinesAO,Machines[],MATCH(J13,Machines[#Headers],0),FALSE))))+VLOOKUP(MachinesUSBDia,Machines[],MATCH(J13,Machines[#Headers],0),FALSE)/2-(J12/2)<0,"-",SQRT(VLOOKUP(MachinesCG,Machines[],MATCH(J13,Machines[#Headers],0),FALSE)^2+(J12/2)^2+2*VLOOKUP(MachinesCG,Machines[],MATCH(J13,Machines[#Headers],0),FALSE)*(J12/2)*SIN(RADIANS(VariableGA-VLOOKUP(MachinesAO,Machines[],MATCH(J13,Machines[#Headers],0),FALSE))))+VLOOKUP(MachinesUSBDia,Machines[],MATCH(J13,Machines[#Headers],0),FALSE)/2-(J12/2)))) -> 85.276027 | K15: =IF(K13="",IF(ISERROR(SQRT(VariableCG^2+(K12/2)^2+2*VariableCG*(K12/2)*SIN(RADIANS(VariableGA-VariableDK)))+VariableUSBDia/2-(K12/2)),"-",IF(SQRT(VariableCG^2+(K12/2)^2+2*VariableCG*(K12/2)*SIN(RADIANS(VariableGA-VariableDK)))+VariableUSBDia/2-(K12/2)<0,"-",SQRT(VariableCG^2+(K12/2)^2+2*VariableCG*(K12/2)*SIN(RADIANS(VariableGA-VariableDK)))+VariableUSBDia/2-(K12/2))),IF(OR(ISERROR(SQRT(VLOOKUP(MachinesCG,Machines[],MATCH(K13,Machines[#Headers],0),FALSE)^2+(K12/2)^2+2*VLOOKUP(MachinesCG,Machines[],MATCH(K13,Machines[#Headers],0),FALSE)*(K12/2)*SIN(RADIANS(VariableGA-VLOOKUP(MachinesAO,Machines[],MATCH(K13,Machines[#Headers],0),FALSE))))+VLOOKUP(MachinesUSBDia,Machines[],MATCH(K13,Machines[#Headers],0),FALSE)/2-(K12/2)),NOT(ISNUMBER(VLOOKUP(MachinesUSBDia,Machines[],MATCH(K13,Machines[#Headers],0),FALSE)))),"-",IF(SQRT(VLOOKUP(MachinesCG,Machines[],MATCH(K13,Machines[#Headers],0),FALSE)^2+(K12/2)^2+2*VLOOKUP(MachinesCG,Machines[],MATCH(K13,Machines[#Headers],0),FALSE)*(K12/2)*SIN(RADIANS(VariableGA-VLOOKUP(MachinesAO,Machines[],MATCH(K13,Machines[#Headers],0),FALSE))))+VLOOKUP(MachinesUSBDia,Machines[],MATCH(K13,Machines[#Headers],0),FALSE)/2-(K12/2)<0,"-",SQRT(VLOOKUP(MachinesCG,Machines[],MATCH(K13,Machines[#Headers],0),FALSE)^2+(K12/2)^2+2*VLOOKUP(MachinesCG,Machines[],MATCH(K13,Machines[#Headers],0),FALSE)*(K12/2)*SIN(RADIANS(VariableGA-VLOOKUP(MachinesAO,Machines[],MATCH(K13,Machines[#Headers],0),FALSE))))+VLOOKUP(MachinesUSBDia,Machines[],MATCH(K13,Machines[#Headers],0),FALSE)/2-(K12/2)))) -> 84.669804 | L15: =IF(L13="",IF(ISERROR(SQRT(VariableCG^2+(L12/2)^2+2*VariableCG*(L12/2)*SIN(RADIANS(VariableGA-VariableDK)))+VariableUSBDia/2-(L12/2)),"-",IF(SQRT(VariableCG^2+(L12/2)^2+2*VariableCG*(L12/2)*SIN(RADIANS(VariableGA-VariableDK)))+VariableUSBDia/2-(L12/2)<0,"-",SQRT(VariableCG^2+(L12/2)^2+2*VariableCG*(L12/2)*SIN(RADIANS(VariableGA-VariableDK)))+VariableUSBDia/2-(L12/2))),IF(OR(ISERROR(SQRT(VLOOKUP(MachinesCG,Machines[],MATCH(L13,Machines[#Headers],0),FALSE)^2+(L12/2)^2+2*VLOOKUP(MachinesCG,Machines[],MATCH(L13,Machines[#Headers],0),FALSE)*(L12/2)*SIN(RADIANS(VariableGA-VLOOKUP(MachinesAO,Machines[],MATCH(L13,Machines[#Headers],0),FALSE))))+VLOOKUP(MachinesUSBDia,Machines[],MATCH(L13,Machines[#Headers],0),FALSE)/2-(L12/2)),NOT(ISNUMBER(VLOOKUP(MachinesUSBDia,Machines[],MATCH(L13,Machines[#Headers],0),FALSE)))),"-",IF(SQRT(VLOOKUP(MachinesCG,Machines[],MATCH(L13,Machines[#Headers],0),FALSE)^2+(L12/2)^2+2*VLOOKUP(MachinesCG,Machines[],MATCH(L13,Machines[#Headers],0),FALSE)*(L12/2)*SIN(RADIANS(VariableGA-VLOOKUP(MachinesAO,Machines[],MATCH(L13,Machines[#Headers],0),FALSE))))+VLOOKUP(MachinesUSBDia,Machines[],MATCH(L13,Machines[#Headers],0),FALSE)/2-(L12/2)<0,"-",SQRT(VLOOKUP(MachinesCG,Machines[],MATCH(L13,Machines[#Headers],0),FALSE)^2+(L12/2)^2+2*VLOOKUP(MachinesCG,Machines[],MATCH(L13,Machines[#Headers],0),FALSE)*(L12/2)*SIN(RADIANS(VariableGA-VLOOKUP(MachinesAO,Machines[],MATCH(L13,Machines[#Headers],0),FALSE))))+VLOOKUP(MachinesUSBDia,Machines[],MATCH(L13,Machines[#Headers],0),FALSE)/2-(L12/2)))) -> 85.109252 | M15: =IF(M13="",IF(ISERROR(SQRT(VariableCG^2+(M12/2)^2+2*VariableCG*(M12/2)*SIN(RADIANS(VariableGA-VariableDK)))+VariableUSBDia/2-(M12/2)),"-",IF(SQRT(VariableCG^2+(M12/2)^2+2*VariableCG*(M12/2)*SIN(RADIANS(VariableGA-VariableDK)))+VariableUSBDia/2-(M12/2)<0,"-",SQRT(VariableCG^2+(M12/2)^2+2*VariableCG*(M12/2)*SIN(RADIANS(VariableGA-VariableDK)))+VariableUSBDia/2-(M12/2))),IF(OR(ISERROR(SQRT(VLOOKUP(MachinesCG,Machines[],MATCH(M13,Machines[#Headers],0),FALSE)^2+(M12/2)^2+2*VLOOKUP(MachinesCG,Machines[],MATCH(M13,Machines[#Headers],0),FALSE)*(M12/2)*SIN(RADIANS(VariableGA-VLOOKUP(MachinesAO,Machines[],MATCH(M13,Machines[#Headers],0),FALSE))))+VLOOKUP(MachinesUSBDia,Machines[],MATCH(M13,Machines[#Headers],0),FALSE)/2-(M12/2)),NOT(ISNUMBER(VLOOKUP(MachinesUSBDia,Machines[],MATCH(M13,Machines[#Headers],0),FALSE)))),"-",IF(SQRT(VLOOKUP(MachinesCG,Machines[],MATCH(M13,Machines[#Headers],0),FALSE)^2+(M12/2)^2+2*VLOOKUP(MachinesCG,Machines[],MATCH(M13,Machines[#Headers],0),FALSE)*(M12/2)*SIN(RADIANS(VariableGA-VLOOKUP(MachinesAO,Machines[],MATCH(M13,Machines[#Headers],0),FALSE))))+VLOOKUP(MachinesUSBDia,Machines[],MATCH(M13,Machines[#Headers],0),FALSE)/2-(M12/2)<0,"-",SQRT(VLOOKUP(MachinesCG,Machines[],MATCH(M13,Machines[#Headers],0),FALSE)^2+(M12/2)^2+2*VLOOKUP(MachinesCG,Machines[],MATCH(M13,Machines[#Headers],0),FALSE)*(M12/2)*SIN(RADIANS(VariableGA-VLOOKUP(MachinesAO,Machines[],MATCH(M13,Machines[#Headers],0),FALSE))))+VLOOKUP(MachinesUSBDia,Machines[],MATCH(M13,Machines[#Headers],0),FALSE)/2-(M12/2)))) -> 85.109252 | N15: =IF(N13="",IF(ISERROR(SQRT(VariableCG^2+(N12/2)^2+2*VariableCG*(N12/2)*SIN(RADIANS(VariableGA-VariableDK)))+VariableUSBDia/2-(N12/2)),"-",IF(SQRT(VariableCG^2+(N12/2)^2+2*VariableCG*(N12/2)*SIN(RADIANS(VariableGA-VariableDK)))+VariableUSBDia/2-(N12/2)<0,"-",SQRT(VariableCG^2+(N12/2)^2+2*VariableCG*(N12/2)*SIN(RADIANS(VariableGA-VariableDK)))+VariableUSBDia/2-(N12/2))),IF(OR(ISERROR(SQRT(VLOOKUP(MachinesCG,Machines[],MATCH(N13,Machines[#Headers],0),FALSE)^2+(N12/2)^2+2*VLOOKUP(MachinesCG,Machines[],MATCH(N13,Machines[#Headers],0),FALSE)*(N12/2)*SIN(RADIANS(VariableGA-VLOOKUP(MachinesAO,Machines[],MATCH(N13,Machines[#Headers],0),FALSE))))+VLOOKUP(MachinesUSBDia,Machines[],MATCH(N13,Machines[#Headers],0),FALSE)/2-(N12/2)),NOT(ISNUMBER(VLOOKUP(MachinesUSBDia,Machines[],MATCH(N13,Machines[#Headers],0),FALSE)))),"-",IF(SQRT(VLOOKUP(MachinesCG,Machines[],MATCH(N13,Machines[#Headers],0),FALSE)^2+(N12/2)^2+2*VLOOKUP(MachinesCG,Machines[],MATCH(N13,Machines[#Headers],0),FALSE)*(N12/2)*SIN(RADIANS(VariableGA-VLOOKUP(MachinesAO,Machines[],MATCH(N13,Machines[#Headers],0),FALSE))))+VLOOKUP(MachinesUSBDia,Machines[],MATCH(N13,Machines[#Headers],0),FALSE)/2-(N12/2)<0,"-",SQRT(VLOOKUP(MachinesCG,Machines[],MATCH(N13,Machines[#Headers],0),FALSE)^2+(N12/2)^2+2*VLOOKUP(MachinesCG,Machines[],MATCH(N13,Machines[#Headers],0),FALSE)*(N12/2)*SIN(RADIANS(VariableGA-VLOOKUP(MachinesAO,Machines[],MATCH(N13,Machines[#Headers],0),FALSE))))+VLOOKUP(MachinesUSBDia,Machines[],MATCH(N13,Machines[#Headers],0),FALSE)/2-(N12/2)))) -> 85.109252 | ... T15: =IF(T13="",IF(ISERROR(SQRT(VariableCG^2+(T12/2)^2+2*VariableCG*(T12/2)*SIN(RADIANS(VariableGA-VariableDK)))+VariableUSBDia/2-(T12/2)),"-",IF(SQRT(VariableCG^2+(T12/2)^2+2*VariableCG*(T12/2)*SIN(RADIANS(VariableGA-VariableDK)))+VariableUSBDia/2-(T12/2)<0,"-",SQRT(VariableCG^2+(T12/2)^2+2*VariableCG*(T12/2)*SIN(RADIANS(VariableGA-VariableDK)))+VariableUSBDia/2-(T12/2))),IF(OR(ISERROR(SQRT(VLOOKUP(MachinesCG,Machines[],MATCH(T13,Machines[#Headers],0),FALSE)^2+(T12/2)^2+2*VLOOKUP(MachinesCG,Machines[],MATCH(T13,Machines[#Headers],0),FALSE)*(T12/2)*SIN(RADIANS(VariableGA-VLOOKUP(MachinesAO,Machines[],MATCH(T13,Machines[#Headers],0),FALSE))))+VLOOKUP(MachinesUSBDia,Machines[],MATCH(T13,Machines[#Headers],0),FALSE)/2-(T12/2)),NOT(ISNUMBER(VLOOKUP(MachinesUSBDia,Machines[],MATCH(T13,Machines[#Headers],0),FALSE)))),"-",IF(SQRT(VLOOKUP(MachinesCG,Machines[],MATCH(T13,Machines[#Headers],0),FALSE)^2+(T12/2)^2+2*VLOOKUP(MachinesCG,Machines[],MATCH(T13,Machines[#Headers],0),FALSE)*(T12/2)*SIN(RADIANS(VariableGA-VLOOKUP(MachinesAO,Machines[],MATCH(T13,Machines[#Headers],0),FALSE))))+VLOOKUP(MachinesUSBDia,Machines[],MATCH(T13,Machines[#Headers],0),FALSE)/2-(T12/2)<0,"-",SQRT(VLOOKUP(MachinesCG,Machines[],MATCH(T13,Machines[#Headers],0),FALSE)^2+(T12/2)^2+2*VLOOKUP(MachinesCG,Machines[],MATCH(T13,Machines[#Headers],0),FALSE)*(T12/2)*SIN(RADIANS(VariableGA-VLOOKUP(MachinesAO,Machines[],MATCH(T13,Machines[#Headers],0),FALSE))))+VLOOKUP(MachinesUSBDia,Machines[],MATCH(T13,Machines[#Headers],0),FALSE)/2-(T12/2)))) -> 92.018304
B16: Universal support bar (USB) diameter U [mm] | C16: =IF(OR($D$16=0,ISTEXT($D$16)),DefaultUSBDia,$D$16) -> 12
B17: Constant HV - Vertical USB [mm] | C17: =IF(OR($D$17=0,ISTEXT($D$17)),DefaultConstantHV,$D$17) -> 49.9 | F17: Height VUSB [mm] | G17: =IF(G13="",IF(ISERROR(SQRT(((G12/2)+(G$15-VariableUSBDia/2))^2-ConstantHV^2)-ConstantVV+VariableUSBDia/2),"-",IF(SQRT(((G12/2)+(G$15-VariableUSBDia/2))^2-ConstantHV^2)-ConstantVV+VariableUSBDia/2<0,"-", SQRT(((G12/2)+(G$15-VariableUSBDia/2))^2-ConstantHV^2)-ConstantVV+VariableUSBDia/2)),IF(OR(ISERROR(SQRT(((G12/2)+(G$15-VLOOKUP(MachinesUSBDia,Machines[],MATCH(G13,Machines[#Headers],0),FALSE)/2))^2-VLOOKUP(MachinesConstantHV,Machines[],MATCH(G13,Machines[#Headers],0),FALSE)^2)-VLOOKUP(MachinesConstantVV,Machines[],MATCH(G13,Machines[#Headers],0),FALSE)+VLOOKUP(MachinesUSBDia,Machines[],MATCH(G13,Machines[#Headers],0),FALSE)/2),NOT(ISNUMBER(VLOOKUP(MachinesConstantHV,Machines[],MATCH(G13,Machines[#Headers],0),FALSE))),NOT(ISNUMBER(VLOOKUP(MachinesConstantVV,Machines[],MATCH(G13,Machines[#Headers],0),FALSE)))),"-",IF(SQRT(((G12/2)+(G$15-VLOOKUP(MachinesUSBDia,Machines[],MATCH(G13,Machines[#Headers],0),FALSE)/2))^2-VLOOKUP(MachinesConstantHV,Machines[],MATCH(G13,Machines[#Headers],0),FALSE)^2)-VLOOKUP(MachinesConstantVV,Machines[],MATCH(G13,Machines[#Headers],0),FALSE)+VLOOKUP(MachinesUSBDia,Machines[],MATCH(G13,Machines[#Headers],0),FALSE)/2<0,"-", SQRT(((G12/2)+(G$15-VLOOKUP(MachinesUSBDia,Machines[],MATCH(G13,Machines[#Headers],0),FALSE)/2))^2-VLOOKUP(MachinesConstantHV,Machines[],MATCH(G13,Machines[#Headers],0),FALSE)^2)-VLOOKUP(MachinesConstantVV,Machines[],MATCH(G13,Machines[#Headers],0),FALSE)+VLOOKUP(MachinesUSBDia,Machines[],MATCH(G13,Machines[#Headers],0),FALSE)/2))) -> 175.21558 | H17: =IF(H13="",IF(ISERROR(SQRT(((H12/2)+(H$15-VariableUSBDia/2))^2-ConstantHV^2)-ConstantVV+VariableUSBDia/2),"-",IF(SQRT(((H12/2)+(H$15-VariableUSBDia/2))^2-ConstantHV^2)-ConstantVV+VariableUSBDia/2<0,"-", SQRT(((H12/2)+(H$15-VariableUSBDia/2))^2-ConstantHV^2)-ConstantVV+VariableUSBDia/2)),IF(OR(ISERROR(SQRT(((H12/2)+(H$15-VLOOKUP(MachinesUSBDia,Machines[],MATCH(H13,Machines[#Headers],0),FALSE)/2))^2-VLOOKUP(MachinesConstantHV,Machines[],MATCH(H13,Machines[#Headers],0),FALSE)^2)-VLOOKUP(MachinesConstantVV,Machines[],MATCH(H13,Machines[#Headers],0),FALSE)+VLOOKUP(MachinesUSBDia,Machines[],MATCH(H13,Machines[#Headers],0),FALSE)/2),NOT(ISNUMBER(VLOOKUP(MachinesConstantHV,Machines[],MATCH(H13,Machines[#Headers],0),FALSE))),NOT(ISNUMBER(VLOOKUP(MachinesConstantVV,Machines[],MATCH(H13,Machines[#Headers],0),FALSE)))),"-",IF(SQRT(((H12/2)+(H$15-VLOOKUP(MachinesUSBDia,Machines[],MATCH(H13,Machines[#Headers],0),FALSE)/2))^2-VLOOKUP(MachinesConstantHV,Machines[],MATCH(H13,Machines[#Headers],0),FALSE)^2)-VLOOKUP(MachinesConstantVV,Machines[],MATCH(H13,Machines[#Headers],0),FALSE)+VLOOKUP(MachinesUSBDia,Machines[],MATCH(H13,Machines[#Headers],0),FALSE)/2<0,"-", SQRT(((H12/2)+(H$15-VLOOKUP(MachinesUSBDia,Machines[],MATCH(H13,Machines[#Headers],0),FALSE)/2))^2-VLOOKUP(MachinesConstantHV,Machines[],MATCH(H13,Machines[#Headers],0),FALSE)^2)-VLOOKUP(MachinesConstantVV,Machines[],MATCH(H13,Machines[#Headers],0),FALSE)+VLOOKUP(MachinesUSBDia,Machines[],MATCH(H13,Machines[#Headers],0),FALSE)/2))) -> 174.81445 | I17: =IF(I13="",IF(ISERROR(SQRT(((I12/2)+(I$15-VariableUSBDia/2))^2-ConstantHV^2)-ConstantVV+VariableUSBDia/2),"-",IF(SQRT(((I12/2)+(I$15-VariableUSBDia/2))^2-ConstantHV^2)-ConstantVV+VariableUSBDia/2<0,"-", SQRT(((I12/2)+(I$15-VariableUSBDia/2))^2-ConstantHV^2)-ConstantVV+VariableUSBDia/2)),IF(OR(ISERROR(SQRT(((I12/2)+(I$15-VLOOKUP(MachinesUSBDia,Machines[],MATCH(I13,Machines[#Headers],0),FALSE)/2))^2-VLOOKUP(MachinesConstantHV,Machines[],MATCH(I13,Machines[#Headers],0),FALSE)^2)-VLOOKUP(MachinesConstantVV,Machines[],MATCH(I13,Machines[#Headers],0),FALSE)+VLOOKUP(MachinesUSBDia,Machines[],MATCH(I13,Machines[#Headers],0),FALSE)/2),NOT(ISNUMBER(VLOOKUP(MachinesConstantHV,Machines[],MATCH(I13,Machines[#Headers],0),FALSE))),NOT(ISNUMBER(VLOOKUP(MachinesConstantVV,Machines[],MATCH(I13,Machines[#Headers],0),FALSE)))),"-",IF(SQRT(((I12/2)+(I$15-VLOOKUP(MachinesUSBDia,Machines[],MATCH(I13,Machines[#Headers],0),FALSE)/2))^2-VLOOKUP(MachinesConstantHV,Machines[],MATCH(I13,Machines[#Headers],0),FALSE)^2)-VLOOKUP(MachinesConstantVV,Machines[],MATCH(I13,Machines[#Headers],0),FALSE)+VLOOKUP(MachinesUSBDia,Machines[],MATCH(I13,Machines[#Headers],0),FALSE)/2<0,"-", SQRT(((I12/2)+(I$15-VLOOKUP(MachinesUSBDia,Machines[],MATCH(I13,Machines[#Headers],0),FALSE)/2))^2-VLOOKUP(MachinesConstantHV,Machines[],MATCH(I13,Machines[#Headers],0),FALSE)^2)-VLOOKUP(MachinesConstantVV,Machines[],MATCH(I13,Machines[#Headers],0),FALSE)+VLOOKUP(MachinesUSBDia,Machines[],MATCH(I13,Machines[#Headers],0),FALSE)/2))) -> 176.62307 | J17: =IF(J13="",IF(ISERROR(SQRT(((J12/2)+(J$15-VariableUSBDia/2))^2-ConstantHV^2)-ConstantVV+VariableUSBDia/2),"-",IF(SQRT(((J12/2)+(J$15-VariableUSBDia/2))^2-ConstantHV^2)-ConstantVV+VariableUSBDia/2<0,"-", SQRT(((J12/2)+(J$15-VariableUSBDia/2))^2-ConstantHV^2)-ConstantVV+VariableUSBDia/2)),IF(OR(ISERROR(SQRT(((J12/2)+(J$15-VLOOKUP(MachinesUSBDia,Machines[],MATCH(J13,Machines[#Headers],0),FALSE)/2))^2-VLOOKUP(MachinesConstantHV,Machines[],MATCH(J13,Machines[#Headers],0),FALSE)^2)-VLOOKUP(MachinesConstantVV,Machines[],MATCH(J13,Machines[#Headers],0),FALSE)+VLOOKUP(MachinesUSBDia,Machines[],MATCH(J13,Machines[#Headers],0),FALSE)/2),NOT(ISNUMBER(VLOOKUP(MachinesConstantHV,Machines[],MATCH(J13,Machines[#Headers],0),FALSE))),NOT(ISNUMBER(VLOOKUP(MachinesConstantVV,Machines[],MATCH(J13,Machines[#Headers],0),FALSE)))),"-",IF(SQRT(((J12/2)+(J$15-VLOOKUP(MachinesUSBDia,Machines[],MATCH(J13,Machines[#Headers],0),FALSE)/2))^2-VLOOKUP(MachinesConstantHV,Machines[],MATCH(J13,Machines[#Headers],0),FALSE)^2)-VLOOKUP(MachinesConstantVV,Machines[],MATCH(J13,Machines[#Headers],0),FALSE)+VLOOKUP(MachinesUSBDia,Machines[],MATCH(J13,Machines[#Headers],0),FALSE)/2<0,"-", SQRT(((J12/2)+(J$15-VLOOKUP(MachinesUSBDia,Machines[],MATCH(J13,Machines[#Headers],0),FALSE)/2))^2-VLOOKUP(MachinesConstantHV,Machines[],MATCH(J13,Machines[#Headers],0),FALSE)^2)-VLOOKUP(MachinesConstantVV,Machines[],MATCH(J13,Machines[#Headers],0),FALSE)+VLOOKUP(MachinesUSBDia,Machines[],MATCH(J13,Machines[#Headers],0),FALSE)/2))) -> 174.61405 | K17: =IF(K13="",IF(ISERROR(SQRT(((K12/2)+(K$15-VariableUSBDia/2))^2-ConstantHV^2)-ConstantVV+VariableUSBDia/2),"-",IF(SQRT(((K12/2)+(K$15-VariableUSBDia/2))^2-ConstantHV^2)-ConstantVV+VariableUSBDia/2<0,"-", SQRT(((K12/2)+(K$15-VariableUSBDia/2))^2-ConstantHV^2)-ConstantVV+VariableUSBDia/2)),IF(OR(ISERROR(SQRT(((K12/2)+(K$15-VLOOKUP(MachinesUSBDia,Machines[],MATCH(K13,Machines[#Headers],0),FALSE)/2))^2-VLOOKUP(MachinesConstantHV,Machines[],MATCH(K13,Machines[#Headers],0),FALSE)^2)-VLOOKUP(MachinesConstantVV,Machines[],MATCH(K13,Machines[#Headers],0),FALSE)+VLOOKUP(MachinesUSBDia,Machines[],MATCH(K13,Machines[#Headers],0),FALSE)/2),NOT(ISNUMBER(VLOOKUP(MachinesConstantHV,Machines[],MATCH(K13,Machines[#Headers],0),FALSE))),NOT(ISNUMBER(VLOOKUP(MachinesConstantVV,Machines[],MATCH(K13,Machines[#Headers],0),FALSE)))),"-",IF(SQRT(((K12/2)+(K$15-VLOOKUP(MachinesUSBDia,Machines[],MATCH(K13,Machines[#Headers],0),FALSE)/2))^2-VLOOKUP(MachinesConstantHV,Machines[],MATCH(K13,Machines[#Headers],0),FALSE)^2)-VLOOKUP(MachinesConstantVV,Machines[],MATCH(K13,Machines[#Headers],0),FALSE)+VLOOKUP(MachinesUSBDia,Machines[],MATCH(K13,Machines[#Headers],0),FALSE)/2<0,"-", SQRT(((K12/2)+(K$15-VLOOKUP(MachinesUSBDia,Machines[],MATCH(K13,Machines[#Headers],0),FALSE)/2))^2-VLOOKUP(MachinesConstantHV,Machines[],MATCH(K13,Machines[#Headers],0),FALSE)^2)-VLOOKUP(MachinesConstantVV,Machines[],MATCH(K13,Machines[#Headers],0),FALSE)+VLOOKUP(MachinesUSBDia,Machines[],MATCH(K13,Machines[#Headers],0),FALSE)/2))) -> 176.82458 | L17: =IF(L13="",IF(ISERROR(SQRT(((L12/2)+(L$15-VariableUSBDia/2))^2-ConstantHV^2)-ConstantVV+VariableUSBDia/2),"-",IF(SQRT(((L12/2)+(L$15-VariableUSBDia/2))^2-ConstantHV^2)-ConstantVV+VariableUSBDia/2<0,"-", SQRT(((L12/2)+(L$15-VariableUSBDia/2))^2-ConstantHV^2)-ConstantVV+VariableUSBDia/2)),IF(OR(ISERROR(SQRT(((L12/2)+(L$15-VLOOKUP(MachinesUSBDia,Machines[],MATCH(L13,Machines[#Headers],0),FALSE)/2))^2-VLOOKUP(MachinesConstantHV,Machines[],MATCH(L13,Machines[#Headers],0),FALSE)^2)-VLOOKUP(MachinesConstantVV,Machines[],MATCH(L13,Machines[#Headers],0),FALSE)+VLOOKUP(MachinesUSBDia,Machines[],MATCH(L13,Machines[#Headers],0),FALSE)/2),NOT(ISNUMBER(VLOOKUP(MachinesConstantHV,Machines[],MATCH(L13,Machines[#Headers],0),FALSE))),NOT(ISNUMBER(VLOOKUP(MachinesConstantVV,Machines[],MATCH(L13,Machines[#Headers],0),FALSE)))),"-",IF(SQRT(((L12/2)+(L$15-VLOOKUP(MachinesUSBDia,Machines[],MATCH(L13,Machines[#Headers],0),FALSE)/2))^2-VLOOKUP(MachinesConstantHV,Machines[],MATCH(L13,Machines[#Headers],0),FALSE)^2)-VLOOKUP(MachinesConstantVV,Machines[],MATCH(L13,Machines[#Headers],0),FALSE)+VLOOKUP(MachinesUSBDia,Machines[],MATCH(L13,Machines[#Headers],0),FALSE)/2<0,"-", SQRT(((L12/2)+(L$15-VLOOKUP(MachinesUSBDia,Machines[],MATCH(L13,Machines[#Headers],0),FALSE)/2))^2-VLOOKUP(MachinesConstantHV,Machines[],MATCH(L13,Machines[#Headers],0),FALSE)^2)-VLOOKUP(MachinesConstantVV,Machines[],MATCH(L13,Machines[#Headers],0),FALSE)+VLOOKUP(MachinesUSBDia,Machines[],MATCH(L13,Machines[#Headers],0),FALSE)/2))) -> 175.21558 | M17: =IF(M13="",IF(ISERROR(SQRT(((M12/2)+(M$15-VariableUSBDia/2))^2-ConstantHV^2)-ConstantVV+VariableUSBDia/2),"-",IF(SQRT(((M12/2)+(M$15-VariableUSBDia/2))^2-ConstantHV^2)-ConstantVV+VariableUSBDia/2<0,"-", SQRT(((M12/2)+(M$15-VariableUSBDia/2))^2-ConstantHV^2)-ConstantVV+VariableUSBDia/2)),IF(OR(ISERROR(SQRT(((M12/2)+(M$15-VLOOKUP(MachinesUSBDia,Machines[],MATCH(M13,Machines[#Headers],0),FALSE)/2))^2-VLOOKUP(MachinesConstantHV,Machines[],MATCH(M13,Machines[#Headers],0),FALSE)^2)-VLOOKUP(MachinesConstantVV,Machines[],MATCH(M13,Machines[#Headers],0),FALSE)+VLOOKUP(MachinesUSBDia,Machines[],MATCH(M13,Machines[#Headers],0),FALSE)/2),NOT(ISNUMBER(VLOOKUP(MachinesConstantHV,Machines[],MATCH(M13,Machines[#Headers],0),FALSE))),NOT(ISNUMBER(VLOOKUP(MachinesConstantVV,Machines[],MATCH(M13,Machines[#Headers],0),FALSE)))),"-",IF(SQRT(((M12/2)+(M$15-VLOOKUP(MachinesUSBDia,Machines[],MATCH(M13,Machines[#Headers],0),FALSE)/2))^2-VLOOKUP(MachinesConstantHV,Machines[],MATCH(M13,Machines[#Headers],0),FALSE)^2)-VLOOKUP(MachinesConstantVV,Machines[],MATCH(M13,Machines[#Headers],0),FALSE)+VLOOKUP(MachinesUSBDia,Machines[],MATCH(M13,Machines[#Headers],0),FALSE)/2<0,"-", SQRT(((M12/2)+(M$15-VLOOKUP(MachinesUSBDia,Machines[],MATCH(M13,Machines[#Headers],0),FALSE)/2))^2-VLOOKUP(MachinesConstantHV,Machines[],MATCH(M13,Machines[#Headers],0),FALSE)^2)-VLOOKUP(MachinesConstantVV,Machines[],MATCH(M13,Machines[#Headers],0),FALSE)+VLOOKUP(MachinesUSBDia,Machines[],MATCH(M13,Machines[#Headers],0),FALSE)/2))) -> 174.89034 | N17: =IF(N13="",IF(ISERROR(SQRT(((N12/2)+(N$15-VariableUSBDia/2))^2-ConstantHV^2)-ConstantVV+VariableUSBDia/2),"-",IF(SQRT(((N12/2)+(N$15-VariableUSBDia/2))^2-ConstantHV^2)-ConstantVV+VariableUSBDia/2<0,"-", SQRT(((N12/2)+(N$15-VariableUSBDia/2))^2-ConstantHV^2)-ConstantVV+VariableUSBDia/2)),IF(OR(ISERROR(SQRT(((N12/2)+(N$15-VLOOKUP(MachinesUSBDia,Machines[],MATCH(N13,Machines[#Headers],0),FALSE)/2))^2-VLOOKUP(MachinesConstantHV,Machines[],MATCH(N13,Machines[#Headers],0),FALSE)^2)-VLOOKUP(MachinesConstantVV,Machines[],MATCH(N13,Machines[#Headers],0),FALSE)+VLOOKUP(MachinesUSBDia,Machines[],MATCH(N13,Machines[#Headers],0),FALSE)/2),NOT(ISNUMBER(VLOOKUP(MachinesConstantHV,Machines[],MATCH(N13,Machines[#Headers],0),FALSE))),NOT(ISNUMBER(VLOOKUP(MachinesConstantVV,Machines[],MATCH(N13,Machines[#Headers],0),FALSE)))),"-",IF(SQRT(((N12/2)+(N$15-VLOOKUP(MachinesUSBDia,Machines[],MATCH(N13,Machines[#Headers],0),FALSE)/2))^2-VLOOKUP(MachinesConstantHV,Machines[],MATCH(N13,Machines[#Headers],0),FALSE)^2)-VLOOKUP(MachinesConstantVV,Machines[],MATCH(N13,Machines[#Headers],0),FALSE)+VLOOKUP(MachinesUSBDia,Machines[],MATCH(N13,Machines[#Headers],0),FALSE)/2<0,"-", SQRT(((N12/2)+(N$15-VLOOKUP(MachinesUSBDia,Machines[],MATCH(N13,Machines[#Headers],0),FALSE)/2))^2-VLOOKUP(MachinesConstantHV,Machines[],MATCH(N13,Machines[#Headers],0),FALSE)^2)-VLOOKUP(MachinesConstantVV,Machines[],MATCH(N13,Machines[#Headers],0),FALSE)+VLOOKUP(MachinesUSBDia,Machines[],MATCH(N13,Machines[#Headers],0),FALSE)/2))) -> 174.76334 | ... T17: =IF(T13="",IF(ISERROR(SQRT(((T12/2)+(T$15-VariableUSBDia/2))^2-ConstantHV^2)-ConstantVV+VariableUSBDia/2),"-",IF(SQRT(((T12/2)+(T$15-VariableUSBDia/2))^2-ConstantHV^2)-ConstantVV+VariableUSBDia/2<0,"-", SQRT(((T12/2)+(T$15-VariableUSBDia/2))^2-ConstantHV^2)-ConstantVV+VariableUSBDia/2)),IF(OR(ISERROR(SQRT(((T12/2)+(T$15-VLOOKUP(MachinesUSBDia,Machines[],MATCH(T13,Machines[#Headers],0),FALSE)/2))^2-VLOOKUP(MachinesConstantHV,Machines[],MATCH(T13,Machines[#Headers],0),FALSE)^2)-VLOOKUP(MachinesConstantVV,Machines[],MATCH(T13,Machines[#Headers],0),FALSE)+VLOOKUP(MachinesUSBDia,Machines[],MATCH(T13,Machines[#Headers],0),FALSE)/2),NOT(ISNUMBER(VLOOKUP(MachinesConstantHV,Machines[],MATCH(T13,Machines[#Headers],0),FALSE))),NOT(ISNUMBER(VLOOKUP(MachinesConstantVV,Machines[],MATCH(T13,Machines[#Headers],0),FALSE)))),"-",IF(SQRT(((T12/2)+(T$15-VLOOKUP(MachinesUSBDia,Machines[],MATCH(T13,Machines[#Headers],0),FALSE)/2))^2-VLOOKUP(MachinesConstantHV,Machines[],MATCH(T13,Machines[#Headers],0),FALSE)^2)-VLOOKUP(MachinesConstantVV,Machines[],MATCH(T13,Machines[#Headers],0),FALSE)+VLOOKUP(MachinesUSBDia,Machines[],MATCH(T13,Machines[#Headers],0),FALSE)/2<0,"-", SQRT(((T12/2)+(T$15-VLOOKUP(MachinesUSBDia,Machines[],MATCH(T13,Machines[#Headers],0),FALSE)/2))^2-VLOOKUP(MachinesConstantHV,Machines[],MATCH(T13,Machines[#Headers],0),FALSE)^2)-VLOOKUP(MachinesConstantVV,Machines[],MATCH(T13,Machines[#Headers],0),FALSE)+VLOOKUP(MachinesUSBDia,Machines[],MATCH(T13,Machines[#Headers],0),FALSE)/2))) -> -
B18: Constant VV - Vertical USB [mm] | C18: =IF(OR($D$18=0,ISTEXT($D$18)),DefaultConstantVV,$D$18) -> 28.7 | F18: Height HUSB [mm] | G18: =IF(G13="",IF(ISERROR(SQRT(((G12/2)+(G$15-VariableUSBDia/2))^2-ConstantHH^2)-ConstantVH+$C$16/2),"-",IF(SQRT(((G12/2)+(G$15-VariableUSBDia/2))^2-ConstantHH^2)-ConstantVH+VariableUSBDia/2<0,"-", SQRT(((G12/2)+(G$15-VariableUSBDia/2))^2-ConstantHH^2)-ConstantVH+VariableUSBDia/2)),IF(OR(ISERROR(SQRT(((G12/2)+(G$15-VLOOKUP(MachinesUSBDia,Machines[],MATCH(G13,Machines[#Headers],0),FALSE)/2))^2-VLOOKUP(MachinesConstantHH,Machines[],MATCH(G13,Machines[#Headers],0),FALSE)^2)-VLOOKUP(MachinesConstantVH,Machines[],MATCH(G13,Machines[#Headers],0),FALSE)+VLOOKUP(MachinesUSBDia,Machines[],MATCH(G13,Machines[#Headers],0),FALSE)/2),NOT(ISNUMBER(VLOOKUP(MachinesConstantHH,Machines[],MATCH(G13,Machines[#Headers],0),FALSE))),NOT(ISNUMBER(VLOOKUP(MachinesConstantVH,Machines[],MATCH(G13,Machines[#Headers],0),FALSE)))),"-",IF(SQRT(((G12/2)+(G$15-VLOOKUP(MachinesUSBDia,Machines[],MATCH(G13,Machines[#Headers],0),FALSE)/2))^2-VLOOKUP(MachinesConstantHH,Machines[],MATCH(G13,Machines[#Headers],0),FALSE)^2)-VLOOKUP(MachinesConstantVH,Machines[],MATCH(G13,Machines[#Headers],0),FALSE)+VLOOKUP(MachinesUSBDia,Machines[],MATCH(G13,Machines[#Headers],0),FALSE)/2<0,"-", SQRT(((G12/2)+(G$15-VLOOKUP(MachinesUSBDia,Machines[],MATCH(G13,Machines[#Headers],0),FALSE)/2))^2-VLOOKUP(MachinesConstantHH,Machines[],MATCH(G13,Machines[#Headers],0),FALSE)^2)-VLOOKUP(MachinesConstantVH,Machines[],MATCH(G13,Machines[#Headers],0),FALSE)+VLOOKUP(MachinesUSBDia,Machines[],MATCH(G13,Machines[#Headers],0),FALSE)/2))) -> 124.84896 | H18: =IF(H13="",IF(ISERROR(SQRT(((H12/2)+(H$15-VariableUSBDia/2))^2-ConstantHH^2)-ConstantVH+$C$16/2),"-",IF(SQRT(((H12/2)+(H$15-VariableUSBDia/2))^2-ConstantHH^2)-ConstantVH+VariableUSBDia/2<0,"-", SQRT(((H12/2)+(H$15-VariableUSBDia/2))^2-ConstantHH^2)-ConstantVH+VariableUSBDia/2)),IF(OR(ISERROR(SQRT(((H12/2)+(H$15-VLOOKUP(MachinesUSBDia,Machines[],MATCH(H13,Machines[#Headers],0),FALSE)/2))^2-VLOOKUP(MachinesConstantHH,Machines[],MATCH(H13,Machines[#Headers],0),FALSE)^2)-VLOOKUP(MachinesConstantVH,Machines[],MATCH(H13,Machines[#Headers],0),FALSE)+VLOOKUP(MachinesUSBDia,Machines[],MATCH(H13,Machines[#Headers],0),FALSE)/2),NOT(ISNUMBER(VLOOKUP(MachinesConstantHH,Machines[],MATCH(H13,Machines[#Headers],0),FALSE))),NOT(ISNUMBER(VLOOKUP(MachinesConstantVH,Machines[],MATCH(H13,Machines[#Headers],0),FALSE)))),"-",IF(SQRT(((H12/2)+(H$15-VLOOKUP(MachinesUSBDia,Machines[],MATCH(H13,Machines[#Headers],0),FALSE)/2))^2-VLOOKUP(MachinesConstantHH,Machines[],MATCH(H13,Machines[#Headers],0),FALSE)^2)-VLOOKUP(MachinesConstantVH,Machines[],MATCH(H13,Machines[#Headers],0),FALSE)+VLOOKUP(MachinesUSBDia,Machines[],MATCH(H13,Machines[#Headers],0),FALSE)/2<0,"-", SQRT(((H12/2)+(H$15-VLOOKUP(MachinesUSBDia,Machines[],MATCH(H13,Machines[#Headers],0),FALSE)/2))^2-VLOOKUP(MachinesConstantHH,Machines[],MATCH(H13,Machines[#Headers],0),FALSE)^2)-VLOOKUP(MachinesConstantVH,Machines[],MATCH(H13,Machines[#Headers],0),FALSE)+VLOOKUP(MachinesUSBDia,Machines[],MATCH(H13,Machines[#Headers],0),FALSE)/2))) -> 124.45191 | I18: =IF(I13="",IF(ISERROR(SQRT(((I12/2)+(I$15-VariableUSBDia/2))^2-ConstantHH^2)-ConstantVH+$C$16/2),"-",IF(SQRT(((I12/2)+(I$15-VariableUSBDia/2))^2-ConstantHH^2)-ConstantVH+VariableUSBDia/2<0,"-", SQRT(((I12/2)+(I$15-VariableUSBDia/2))^2-ConstantHH^2)-ConstantVH+VariableUSBDia/2)),IF(OR(ISERROR(SQRT(((I12/2)+(I$15-VLOOKUP(MachinesUSBDia,Machines[],MATCH(I13,Machines[#Headers],0),FALSE)/2))^2-VLOOKUP(MachinesConstantHH,Machines[],MATCH(I13,Machines[#Headers],0),FALSE)^2)-VLOOKUP(MachinesConstantVH,Machines[],MATCH(I13,Machines[#Headers],0),FALSE)+VLOOKUP(MachinesUSBDia,Machines[],MATCH(I13,Machines[#Headers],0),FALSE)/2),NOT(ISNUMBER(VLOOKUP(MachinesConstantHH,Machines[],MATCH(I13,Machines[#Headers],0),FALSE))),NOT(ISNUMBER(VLOOKUP(MachinesConstantVH,Machines[],MATCH(I13,Machines[#Headers],0),FALSE)))),"-",IF(SQRT(((I12/2)+(I$15-VLOOKUP(MachinesUSBDia,Machines[],MATCH(I13,Machines[#Headers],0),FALSE)/2))^2-VLOOKUP(MachinesConstantHH,Machines[],MATCH(I13,Machines[#Headers],0),FALSE)^2)-VLOOKUP(MachinesConstantVH,Machines[],MATCH(I13,Machines[#Headers],0),FALSE)+VLOOKUP(MachinesUSBDia,Machines[],MATCH(I13,Machines[#Headers],0),FALSE)/2<0,"-", SQRT(((I12/2)+(I$15-VLOOKUP(MachinesUSBDia,Machines[],MATCH(I13,Machines[#Headers],0),FALSE)/2))^2-VLOOKUP(MachinesConstantHH,Machines[],MATCH(I13,Machines[#Headers],0),FALSE)^2)-VLOOKUP(MachinesConstantVH,Machines[],MATCH(I13,Machines[#Headers],0),FALSE)+VLOOKUP(MachinesUSBDia,Machines[],MATCH(I13,Machines[#Headers],0),FALSE)/2))) -> 126.24223 | J18: =IF(J13="",IF(ISERROR(SQRT(((J12/2)+(J$15-VariableUSBDia/2))^2-ConstantHH^2)-ConstantVH+$C$16/2),"-",IF(SQRT(((J12/2)+(J$15-VariableUSBDia/2))^2-ConstantHH^2)-ConstantVH+VariableUSBDia/2<0,"-", SQRT(((J12/2)+(J$15-VariableUSBDia/2))^2-ConstantHH^2)-ConstantVH+VariableUSBDia/2)),IF(OR(ISERROR(SQRT(((J12/2)+(J$15-VLOOKUP(MachinesUSBDia,Machines[],MATCH(J13,Machines[#Headers],0),FALSE)/2))^2-VLOOKUP(MachinesConstantHH,Machines[],MATCH(J13,Machines[#Headers],0),FALSE)^2)-VLOOKUP(MachinesConstantVH,Machines[],MATCH(J13,Machines[#Headers],0),FALSE)+VLOOKUP(MachinesUSBDia,Machines[],MATCH(J13,Machines[#Headers],0),FALSE)/2),NOT(ISNUMBER(VLOOKUP(MachinesConstantHH,Machines[],MATCH(J13,Machines[#Headers],0),FALSE))),NOT(ISNUMBER(VLOOKUP(MachinesConstantVH,Machines[],MATCH(J13,Machines[#Headers],0),FALSE)))),"-",IF(SQRT(((J12/2)+(J$15-VLOOKUP(MachinesUSBDia,Machines[],MATCH(J13,Machines[#Headers],0),FALSE)/2))^2-VLOOKUP(MachinesConstantHH,Machines[],MATCH(J13,Machines[#Headers],0),FALSE)^2)-VLOOKUP(MachinesConstantVH,Machines[],MATCH(J13,Machines[#Headers],0),FALSE)+VLOOKUP(MachinesUSBDia,Machines[],MATCH(J13,Machines[#Headers],0),FALSE)/2<0,"-", SQRT(((J12/2)+(J$15-VLOOKUP(MachinesUSBDia,Machines[],MATCH(J13,Machines[#Headers],0),FALSE)/2))^2-VLOOKUP(MachinesConstantHH,Machines[],MATCH(J13,Machines[#Headers],0),FALSE)^2)-VLOOKUP(MachinesConstantVH,Machines[],MATCH(J13,Machines[#Headers],0),FALSE)+VLOOKUP(MachinesUSBDia,Machines[],MATCH(J13,Machines[#Headers],0),FALSE)/2))) -> 124.25356 | K18: =IF(K13="",IF(ISERROR(SQRT(((K12/2)+(K$15-VariableUSBDia/2))^2-ConstantHH^2)-ConstantVH+$C$16/2),"-",IF(SQRT(((K12/2)+(K$15-VariableUSBDia/2))^2-ConstantHH^2)-ConstantVH+VariableUSBDia/2<0,"-", SQRT(((K12/2)+(K$15-VariableUSBDia/2))^2-ConstantHH^2)-ConstantVH+VariableUSBDia/2)),IF(OR(ISERROR(SQRT(((K12/2)+(K$15-VLOOKUP(MachinesUSBDia,Machines[],MATCH(K13,Machines[#Headers],0),FALSE)/2))^2-VLOOKUP(MachinesConstantHH,Machines[],MATCH(K13,Machines[#Headers],0),FALSE)^2)-VLOOKUP(MachinesConstantVH,Machines[],MATCH(K13,Machines[#Headers],0),FALSE)+VLOOKUP(MachinesUSBDia,Machines[],MATCH(K13,Machines[#Headers],0),FALSE)/2),NOT(ISNUMBER(VLOOKUP(MachinesConstantHH,Machines[],MATCH(K13,Machines[#Headers],0),FALSE))),NOT(ISNUMBER(VLOOKUP(MachinesConstantVH,Machines[],MATCH(K13,Machines[#Headers],0),FALSE)))),"-",IF(SQRT(((K12/2)+(K$15-VLOOKUP(MachinesUSBDia,Machines[],MATCH(K13,Machines[#Headers],0),FALSE)/2))^2-VLOOKUP(MachinesConstantHH,Machines[],MATCH(K13,Machines[#Headers],0),FALSE)^2)-VLOOKUP(MachinesConstantVH,Machines[],MATCH(K13,Machines[#Headers],0),FALSE)+VLOOKUP(MachinesUSBDia,Machines[],MATCH(K13,Machines[#Headers],0),FALSE)/2<0,"-", SQRT(((K12/2)+(K$15-VLOOKUP(MachinesUSBDia,Machines[],MATCH(K13,Machines[#Headers],0),FALSE)/2))^2-VLOOKUP(MachinesConstantHH,Machines[],MATCH(K13,Machines[#Headers],0),FALSE)^2)-VLOOKUP(MachinesConstantVH,Machines[],MATCH(K13,Machines[#Headers],0),FALSE)+VLOOKUP(MachinesUSBDia,Machines[],MATCH(K13,Machines[#Headers],0),FALSE)/2))) -> 126.44173 | L18: =IF(L13="",IF(ISERROR(SQRT(((L12/2)+(L$15-VariableUSBDia/2))^2-ConstantHH^2)-ConstantVH+$C$16/2),"-",IF(SQRT(((L12/2)+(L$15-VariableUSBDia/2))^2-ConstantHH^2)-ConstantVH+VariableUSBDia/2<0,"-", SQRT(((L12/2)+(L$15-VariableUSBDia/2))^2-ConstantHH^2)-ConstantVH+VariableUSBDia/2)),IF(OR(ISERROR(SQRT(((L12/2)+(L$15-VLOOKUP(MachinesUSBDia,Machines[],MATCH(L13,Machines[#Headers],0),FALSE)/2))^2-VLOOKUP(MachinesConstantHH,Machines[],MATCH(L13,Machines[#Headers],0),FALSE)^2)-VLOOKUP(MachinesConstantVH,Machines[],MATCH(L13,Machines[#Headers],0),FALSE)+VLOOKUP(MachinesUSBDia,Machines[],MATCH(L13,Machines[#Headers],0),FALSE)/2),NOT(ISNUMBER(VLOOKUP(MachinesConstantHH,Machines[],MATCH(L13,Machines[#Headers],0),FALSE))),NOT(ISNUMBER(VLOOKUP(MachinesConstantVH,Machines[],MATCH(L13,Machines[#Headers],0),FALSE)))),"-",IF(SQRT(((L12/2)+(L$15-VLOOKUP(MachinesUSBDia,Machines[],MATCH(L13,Machines[#Headers],0),FALSE)/2))^2-VLOOKUP(MachinesConstantHH,Machines[],MATCH(L13,Machines[#Headers],0),FALSE)^2)-VLOOKUP(MachinesConstantVH,Machines[],MATCH(L13,Machines[#Headers],0),FALSE)+VLOOKUP(MachinesUSBDia,Machines[],MATCH(L13,Machines[#Headers],0),FALSE)/2<0,"-", SQRT(((L12/2)+(L$15-VLOOKUP(MachinesUSBDia,Machines[],MATCH(L13,Machines[#Headers],0),FALSE)/2))^2-VLOOKUP(MachinesConstantHH,Machines[],MATCH(L13,Machines[#Headers],0),FALSE)^2)-VLOOKUP(MachinesConstantVH,Machines[],MATCH(L13,Machines[#Headers],0),FALSE)+VLOOKUP(MachinesUSBDia,Machines[],MATCH(L13,Machines[#Headers],0),FALSE)/2))) -> 124.84896 | M18: =IF(M13="",IF(ISERROR(SQRT(((M12/2)+(M$15-VariableUSBDia/2))^2-ConstantHH^2)-ConstantVH+$C$16/2),"-",IF(SQRT(((M12/2)+(M$15-VariableUSBDia/2))^2-ConstantHH^2)-ConstantVH+VariableUSBDia/2<0,"-", SQRT(((M12/2)+(M$15-VariableUSBDia/2))^2-ConstantHH^2)-ConstantVH+VariableUSBDia/2)),IF(OR(ISERROR(SQRT(((M12/2)+(M$15-VLOOKUP(MachinesUSBDia,Machines[],MATCH(M13,Machines[#Headers],0),FALSE)/2))^2-VLOOKUP(MachinesConstantHH,Machines[],MATCH(M13,Machines[#Headers],0),FALSE)^2)-VLOOKUP(MachinesConstantVH,Machines[],MATCH(M13,Machines[#Headers],0),FALSE)+VLOOKUP(MachinesUSBDia,Machines[],MATCH(M13,Machines[#Headers],0),FALSE)/2),NOT(ISNUMBER(VLOOKUP(MachinesConstantHH,Machines[],MATCH(M13,Machines[#Headers],0),FALSE))),NOT(ISNUMBER(VLOOKUP(MachinesConstantVH,Machines[],MATCH(M13,Machines[#Headers],0),FALSE)))),"-",IF(SQRT(((M12/2)+(M$15-VLOOKUP(MachinesUSBDia,Machines[],MATCH(M13,Machines[#Headers],0),FALSE)/2))^2-VLOOKUP(MachinesConstantHH,Machines[],MATCH(M13,Machines[#Headers],0),FALSE)^2)-VLOOKUP(MachinesConstantVH,Machines[],MATCH(M13,Machines[#Headers],0),FALSE)+VLOOKUP(MachinesUSBDia,Machines[],MATCH(M13,Machines[#Headers],0),FALSE)/2<0,"-", SQRT(((M12/2)+(M$15-VLOOKUP(MachinesUSBDia,Machines[],MATCH(M13,Machines[#Headers],0),FALSE)/2))^2-VLOOKUP(MachinesConstantHH,Machines[],MATCH(M13,Machines[#Headers],0),FALSE)^2)-VLOOKUP(MachinesConstantVH,Machines[],MATCH(M13,Machines[#Headers],0),FALSE)+VLOOKUP(MachinesUSBDia,Machines[],MATCH(M13,Machines[#Headers],0),FALSE)/2))) -> 124.94896 | N18: =IF(N13="",IF(ISERROR(SQRT(((N12/2)+(N$15-VariableUSBDia/2))^2-ConstantHH^2)-ConstantVH+$C$16/2),"-",IF(SQRT(((N12/2)+(N$15-VariableUSBDia/2))^2-ConstantHH^2)-ConstantVH+VariableUSBDia/2<0,"-", SQRT(((N12/2)+(N$15-VariableUSBDia/2))^2-ConstantHH^2)-ConstantVH+VariableUSBDia/2)),IF(OR(ISERROR(SQRT(((N12/2)+(N$15-VLOOKUP(MachinesUSBDia,Machines[],MATCH(N13,Machines[#Headers],0),FALSE)/2))^2-VLOOKUP(MachinesConstantHH,Machines[],MATCH(N13,Machines[#Headers],0),FALSE)^2)-VLOOKUP(MachinesConstantVH,Machines[],MATCH(N13,Machines[#Headers],0),FALSE)+VLOOKUP(MachinesUSBDia,Machines[],MATCH(N13,Machines[#Headers],0),FALSE)/2),NOT(ISNUMBER(VLOOKUP(MachinesConstantHH,Machines[],MATCH(N13,Machines[#Headers],0),FALSE))),NOT(ISNUMBER(VLOOKUP(MachinesConstantVH,Machines[],MATCH(N13,Machines[#Headers],0),FALSE)))),"-",IF(SQRT(((N12/2)+(N$15-VLOOKUP(MachinesUSBDia,Machines[],MATCH(N13,Machines[#Headers],0),FALSE)/2))^2-VLOOKUP(MachinesConstantHH,Machines[],MATCH(N13,Machines[#Headers],0),FALSE)^2)-VLOOKUP(MachinesConstantVH,Machines[],MATCH(N13,Machines[#Headers],0),FALSE)+VLOOKUP(MachinesUSBDia,Machines[],MATCH(N13,Machines[#Headers],0),FALSE)/2<0,"-", SQRT(((N12/2)+(N$15-VLOOKUP(MachinesUSBDia,Machines[],MATCH(N13,Machines[#Headers],0),FALSE)/2))^2-VLOOKUP(MachinesConstantHH,Machines[],MATCH(N13,Machines[#Headers],0),FALSE)^2)-VLOOKUP(MachinesConstantVH,Machines[],MATCH(N13,Machines[#Headers],0),FALSE)+VLOOKUP(MachinesUSBDia,Machines[],MATCH(N13,Machines[#Headers],0),FALSE)/2))) -> 126.14896 | ... T18: =IF(T13="",IF(ISERROR(SQRT(((T12/2)+(T$15-VariableUSBDia/2))^2-ConstantHH^2)-ConstantVH+$C$16/2),"-",IF(SQRT(((T12/2)+(T$15-VariableUSBDia/2))^2-ConstantHH^2)-ConstantVH+VariableUSBDia/2<0,"-", SQRT(((T12/2)+(T$15-VariableUSBDia/2))^2-ConstantHH^2)-ConstantVH+VariableUSBDia/2)),IF(OR(ISERROR(SQRT(((T12/2)+(T$15-VLOOKUP(MachinesUSBDia,Machines[],MATCH(T13,Machines[#Headers],0),FALSE)/2))^2-VLOOKUP(MachinesConstantHH,Machines[],MATCH(T13,Machines[#Headers],0),FALSE)^2)-VLOOKUP(MachinesConstantVH,Machines[],MATCH(T13,Machines[#Headers],0),FALSE)+VLOOKUP(MachinesUSBDia,Machines[],MATCH(T13,Machines[#Headers],0),FALSE)/2),NOT(ISNUMBER(VLOOKUP(MachinesConstantHH,Machines[],MATCH(T13,Machines[#Headers],0),FALSE))),NOT(ISNUMBER(VLOOKUP(MachinesConstantVH,Machines[],MATCH(T13,Machines[#Headers],0),FALSE)))),"-",IF(SQRT(((T12/2)+(T$15-VLOOKUP(MachinesUSBDia,Machines[],MATCH(T13,Machines[#Headers],0),FALSE)/2))^2-VLOOKUP(MachinesConstantHH,Machines[],MATCH(T13,Machines[#Headers],0),FALSE)^2)-VLOOKUP(MachinesConstantVH,Machines[],MATCH(T13,Machines[#Headers],0),FALSE)+VLOOKUP(MachinesUSBDia,Machines[],MATCH(T13,Machines[#Headers],0),FALSE)/2<0,"-", SQRT(((T12/2)+(T$15-VLOOKUP(MachinesUSBDia,Machines[],MATCH(T13,Machines[#Headers],0),FALSE)/2))^2-VLOOKUP(MachinesConstantHH,Machines[],MATCH(T13,Machines[#Headers],0),FALSE)^2)-VLOOKUP(MachinesConstantVH,Machines[],MATCH(T13,Machines[#Headers],0),FALSE)+VLOOKUP(MachinesUSBDia,Machines[],MATCH(T13,Machines[#Headers],0),FALSE)/2))) -> 103.42524
